<?xml version='1.0'?>

<robot name="my_robot" xmlns:xacro="http://www.ros.org/wiki/xacro">

  <xacro:include filename="$(find my_robot)/urdf/my_robot.gazebo" />

  <material name="blue">
    <color rgba="0 0 0.8 1"/>
  </material>

  <material name="white">
    <color rgba="1 1 1 1"/>
  </material>

  <material name="black">
    <color rgba="0 0 0 1"/>
  </material>

  <link name="robot_footprint"></link>

  <joint name="robot_footprint_joint" type="fixed">
    <origin xyz="0 0 0" rpy="0 0 0" />
    <parent link="robot_footprint"/>
    <child link="chassis" />
  </joint>

  <link name='chassis'>
    <pose>0 0 0.1 0 0 0</pose>

    <inertial>
      <mass value="15.0"/>
      <origin xyz="0.0 0 0" rpy=" 0 0 0"/>
      <inertia
          ixx="0.1" ixy="0" ixz="0"
          iyy="0.1" iyz="0"
          izz="0.1"
      />
    </inertial>

    <collision name='collision'>
      <origin xyz="0 0 0" rpy=" 0 0 0"/> 
      <geometry>
        <box size=".4 .2 .1"/>
      </geometry>
    </collision>

    <visual name='chassis_visual'>
      <origin xyz="0 0 0" rpy=" 0 0 0"/>
      <geometry>
        <box size=".4 .2 .1"/>
      </geometry>
      <material name="blue"/>
    </visual>


    <collision name='back_caster_collision'>
      <origin xyz="-0.15 0 -0.05" rpy=" 0 0 0"/>
      <geometry>
        <sphere radius="0.0499"/>
      </geometry>
    </collision>

    <visual name='back_caster_visual'>
      <origin xyz="-0.15 0 -0.05" rpy=" 0 0 0"/>
      <geometry>
        <sphere radius="0.05"/>
      </geometry>
    </visual>

    <collision name='front_caster_collision'>
      <origin xyz="0.15 0 -0.05" rpy=" 0 0 0"/>
      <geometry>
        <sphere radius="0.0499"/>
      </geometry>
    </collision>

    <visual name='front_caster_visual'>
      <origin xyz="0.15 0 -0.05" rpy=" 0 0 0"/>
      <geometry>
        <sphere radius="0.05"/>
      </geometry>
    </visual>

  </link>


  <!--defining macro for wheels-->

  <xacro:macro name="wheel_inertial" params="mass">
        <inertial>
                <mass value="${mass}" />
                <inertia ixx="0.1" ixy="0.0" ixz="0.0"
                     iyy="0.1" iyz="0.0"
                     izz="0.1" />
        </inertial>
    </xacro:macro>

  <xacro:macro name="wheel" params="prefix reflect">
      <link name="${prefix}_wheel">
          <visual>
              <geometry>
                  <cylinder radius="0.1" length="0.05"/>
              </geometry>
              <origin xyz="0 0 0" rpy="0 ${pi/2} ${pi/2}"/>
              <material name="black"/>
          </visual>
          <collision>
              <geometry>
                  <cylinder radius="0.1" length="0.05"/>
              </geometry>
              <origin xyz="0 0 0" rpy="0 ${pi/2} ${pi/2}"/>
          </collision>
          <xacro:wheel_inertial mass="5"/>
      </link>

      <joint name="${prefix}_wheel_hinge" type="continuous">
          <parent link="chassis"/>
          <child link="${prefix}_wheel"/>
          <origin xyz="0 ${reflect*(0.15)} 0.0" />
          <axis xyz="0 1 0" rpy="0 0 0"/>
          <limit effort="10000" velocity="1000"/>
          <dynamics damping="1.0" friction="1.0"/>
      </joint>

      <!-- A bunch of stuff cut -->
  </xacro:macro>
  <xacro:wheel prefix="right" reflect="-1" />
  <xacro:wheel prefix="left" reflect="1" />


  <!-- Adding camera -->

  <link name='camera'>

    <inertial>
      <mass value="0.1"/>
      <origin xyz="0.0 0 0" rpy=" 0 0 0"/>
      <inertia
          ixx="1e-6" ixy="0" ixz="0"
          iyy="1e-6" iyz="0"
          izz="1e-6"
      />
    </inertial>

    <collision name='camera_collision'>
      <origin xyz="0 0 0" rpy=" 0 0 0"/> 
      <geometry>
        <box size=".05 .05 .05"/>
      </geometry>
    </collision>

    <visual name='camera_visual'>
      <origin xyz="0 0 0" rpy=" 0 0 0"/>
      <geometry>
        <box size=".05 .05 .05"/>
      </geometry>
    </visual>

  </link>

  <joint name="camera_chassis_joint" type="fixed">
    <axis xyz="0 1 0"/>
    <origin xyz="0.2 0 0" rpy="0 0 0" />
    <parent link="chassis"/>
    <child link="camera" />
  </joint>


<!-- Adding LIDAR -->

  <link name='hokuyo'>

    <inertial>
      <mass value="1e-5"/>
      <origin xyz="0.0 0 0" rpy=" 0 0 0"/>
      <inertia
          ixx="1e-6" ixy="0" ixz="0"
          iyy="1e-6" iyz="0"
          izz="1e-6"
      />
    </inertial>

    <collision name='hokuyo_collision'>
      <origin xyz="0 0 0" rpy=" 0 0 0"/> 
      <geometry>
        <box size="0.1 0.1 0.1"/>
      </geometry>
    </collision>

    <visual name='hokuyo_visual'>
      <origin xyz="0 0 0" rpy=" 0 0 0"/>
      <geometry >
        <mesh filename= "package://my_robot/meshes/hokuyo.dae"/>
      </geometry>
    </visual>

  </link>

  <joint name="hokuyo_joint" type="fixed">
    <axis xyz="0 1 0"/>
    <origin xyz="0.15 0 0.1" rpy="0 0 0" />
    <parent link="chassis"/>
    <child link="hokuyo" />
  </joint>




</robot>

